<?xml version="1.0" encoding="utf-8" ?>
<!-- =================================================================================== -->
<!-- |    This document was autogenerated by xacro from /home/nejc/ms_projektna_ws/src/fanuc_cr7ia_support/urdf/cr7ial.xacro | -->
<!-- |    EDITING THIS FILE BY HAND IS NOT RECOMMENDED                                 | -->
<!-- =================================================================================== -->
<robot name="fanuc_cr7ial">
    <!-- links: main serial chain -->
    <link name="base_link">
        <visual>
            <origin rpy="0 0 0" xyz="0 0 0" />
            <geometry>
                <mesh filename="package://fanuc_cr7ia_support/meshes/cr7ia/visual/base_link.stl" />
            </geometry>
            <material name="">
                <color rgba="0.239215686275 0.239215686275 0.239215686275 1.0" />
            </material>
        </visual>
        <collision>
            <origin rpy="0 0 0" xyz="0 0 0" />
            <geometry>
                <mesh filename="package://fanuc_cr7ia_support/meshes/cr7ia/collision/base_link.stl" />
            </geometry>
        </collision>
        
<inertial>
            <mass value="0.1" />
            <inertia ixx="0.03" iyy="0.03" izz="0.03" ixy="0.0" ixz="0.0" iyz="0.0" />
        </inertial>

    </link>
    <link name="link_1">
        <visual>
            <origin rpy="0 0 0" xyz="0 0 0" />
            <geometry>
                <mesh filename="package://fanuc_cr7ia_support/meshes/cr7ia/visual/link_1.stl" />
            </geometry>
            <material name="">
                <color rgba="0.0 0.607843137255 0.274509803922 1.0" />
            </material>
        </visual>
        <collision>
            <origin rpy="0 0 0" xyz="0 0 0" />
            <geometry>
                <mesh filename="package://fanuc_cr7ia_support/meshes/cr7ia/collision/link_1.stl" />
            </geometry>
        </collision>
        
<inertial>
            <mass value="0.1" />
            <inertia ixx="0.03" iyy="0.03" izz="0.03" ixy="0.0" ixz="0.0" iyz="0.0" />
        </inertial>

    </link>
    <link name="link_2">
        <visual>
            <origin rpy="0 0 0" xyz="0 0 0" />
            <geometry>
                <mesh filename="package://fanuc_cr7ia_support/meshes/cr7ial/visual/link_2.stl" />
            </geometry>
            <material name="">
                <color rgba="0.0 0.607843137255 0.274509803922 1.0" />
            </material>
        </visual>
        <collision>
            <origin rpy="0 0 0" xyz="0 0 0" />
            <geometry>
                <mesh filename="package://fanuc_cr7ia_support/meshes/cr7ial/collision/link_2.stl" />
            </geometry>
        </collision>
        
<inertial>
            <mass value="0.1" />
            <inertia ixx="0.03" iyy="0.03" izz="0.03" ixy="0.0" ixz="0.0" iyz="0.0" />
        </inertial>

    </link>
    <link name="link_3">
        <visual>
            <origin rpy="0 0 0" xyz="0 0 0" />
            <geometry>
                <mesh filename="package://fanuc_cr7ia_support/meshes/cr7ia/visual/link_3.stl" />
            </geometry>
            <material name="">
                <color rgba="0.0 0.607843137255 0.274509803922 1.0" />
            </material>
        </visual>
        <collision>
            <origin rpy="0 0 0" xyz="0 0 0" />
            <geometry>
                <mesh filename="package://fanuc_cr7ia_support/meshes/cr7ia/collision/link_3.stl" />
            </geometry>
        </collision>
        
<inertial>
            <mass value="0.1" />
            <inertia ixx="0.03" iyy="0.03" izz="0.03" ixy="0.0" ixz="0.0" iyz="0.0" />
        </inertial>

    </link>
    <link name="link_4">
        <visual>
            <origin rpy="0 0 0" xyz="0 0 0" />
            <geometry>
                <mesh filename="package://fanuc_cr7ia_support/meshes/cr7ial/visual/link_4.stl" />
            </geometry>
            <material name="">
                <color rgba="0.0 0.607843137255 0.274509803922 1.0" />
            </material>
        </visual>
        <collision>
            <origin rpy="0 0 0" xyz="0 0 0" />
            <geometry>
                <mesh filename="package://fanuc_cr7ia_support/meshes/cr7ial/collision/link_4.stl" />
            </geometry>
        </collision>
        
<inertial>
            <mass value="0.1" />
            <inertia ixx="0.03" iyy="0.03" izz="0.03" ixy="0.0" ixz="0.0" iyz="0.0" />
        </inertial>

    </link>
    <link name="link_5">
        <visual>
            <origin rpy="0 0 0" xyz="0 0 0" />
            <geometry>
                <mesh filename="package://fanuc_cr7ia_support/meshes/cr7ia/visual/link_5.stl" />
            </geometry>
            <material name="">
                <color rgba="0.0 0.607843137255 0.274509803922 1.0" />
            </material>
        </visual>
        <collision>
            <origin rpy="0 0 0" xyz="0 0 0" />
            <geometry>
                <mesh filename="package://fanuc_cr7ia_support/meshes/cr7ia/collision/link_5.stl" />
            </geometry>
        </collision>
        
<inertial>
            <mass value="0.1" />
            <inertia ixx="0.03" iyy="0.03" izz="0.03" ixy="0.0" ixz="0.0" iyz="0.0" />
        </inertial>

    </link>
    <link name="link_6">
        <visual>
            <origin rpy="0 0 0" xyz="0 0 0" />
            <geometry>
                <mesh filename="package://fanuc_cr7ia_support/meshes/cr7ia/visual/link_6.stl" />
            </geometry>
            <material name="">
                <color rgba="0.239215686275 0.239215686275 0.239215686275 1.0" />
            </material>
        </visual>
        <collision>
            <origin rpy="0 0 0" xyz="0 0 0" />
            <geometry>
                <mesh filename="package://fanuc_cr7ia_support/meshes/cr7ia/collision/link_6.stl" />
            </geometry>
        </collision>
        
<inertial>
            <mass value="0.1" />
            <inertia ixx="0.03" iyy="0.03" izz="0.03" ixy="0.0" ixz="0.0" iyz="0.0" />
        </inertial>

    </link>
    <!-- joints: main serial chain -->
    <joint name="joint_1" type="revolute">
        <origin rpy="0 0 0" xyz="0 0 0.457" />
        <parent link="base_link" />
        <child link="link_1" />
        <axis xyz="0 0 1" />
        <dynamics damping="1.0" />
        <limit effort="0" lower="-2.9671" upper="2.9671" velocity="6.4577" />
    </joint>
    <joint name="joint_2" type="revolute">
        <origin rpy="0 0 0" xyz="0.05 0 0" />
        <parent link="link_1" />
        <child link="link_2" />
        <axis xyz="0 1 0" />
        <dynamics damping="1.0" />
        <limit effort="0" lower="-1.15192" upper="1.74533" velocity="5.4105" />
    </joint>
    <joint name="joint_3" type="revolute">
        <origin rpy="0 0 0" xyz="0 0 0.440" />
        <parent link="link_2" />
        <child link="link_3" />
        <axis xyz="0 -1 0" />
        <dynamics damping="1.0" />
        <limit effort="0" lower="-0.802851" upper="3.10669" velocity="7.1558" />
    </joint>
    <joint name="joint_4" type="revolute">
        <origin rpy="0 0 0" xyz="0 0 0.035" />
        <parent link="link_3" />
        <child link="link_4" />
        <axis xyz="-1 0 0" />
        <dynamics damping="1.0" />
        <limit effort="0" lower="-3.3161" upper="3.3161" velocity="9.5993" />
    </joint>
    <joint name="joint_5" type="revolute">
        <origin rpy="0 0 0" xyz="0.420 0 0" />
        <parent link="link_4" />
        <child link="link_5" />
        <axis xyz="0 -1 0" />
        <dynamics damping="1.0" />
        <limit effort="0" lower="-2.0944" upper="2.0944" velocity="9.5120" />
    </joint>
    <joint name="joint_6" type="revolute">
        <origin rpy="0 0 0" xyz="0.080 0 0" />
        <parent link="link_5" />
        <child link="link_6" />
        <axis xyz="-1 0 0" />
        <dynamics damping="1.0" />
        <limit effort="0" lower="-6.2832" upper="6.2832" velocity="17.4532" />
    </joint>
    <!-- WORLD LINK -->
    <link name="world" />
    <joint name="world" type="fixed">
        <origin rpy="0 0 0" xyz="0 0 0" />
        <parent link="world" />
        <child link="base_link" />
    </joint>

    <!-- ROS-Industrial 'base' frame: base_link to Fanuc World Coordinates transform -->
    <link name="base" />
    <joint name="base_link-base" type="fixed">
        <origin rpy="0 0 0" xyz="0 0 0.457" />
        <parent link="base_link" />
        <child link="base" />
    </joint>
    <!-- ROS-Industrial 'flange' frame: attachment point for EEF models -->
    <link name="flange" />
    <joint name="joint_6-flange" type="fixed">
        <origin rpy="0 0 0" xyz="0 0 0" />
        <parent link="link_6" />
        <child link="flange" />
    </joint>
    <!-- ROS-Industrial 'tool0' frame: all-zeros tool frame -->
    <link name="tool0" />
    <joint name="link_6-tool0" type="fixed">
        <origin rpy="3.14159265359 -1.57079632679 0" xyz="0 0 0" />
        <parent link="flange" />
        <child link="tool0" />
    </joint>

    <!-- MATERIALS GAZEBO -->
    <gazebo reference="base_link">
        <material>Gazebo/Grey</material>
    </gazebo>
    <gazebo reference="link_1">
        <material>Gazebo/Green</material>
    </gazebo>
    <gazebo reference="link_2">
        <material>Gazebo/Green</material>
    </gazebo>
    <gazebo reference="link_3">
        <material>Gazebo/Green</material>
    </gazebo>
    <gazebo reference="link_4">
        <material>Gazebo/Green</material>
    </gazebo>
    <gazebo reference="link_5">
        <material>Gazebo/Green</material>
    </gazebo>
    <gazebo reference="link_6">
        <material>Gazebo/Green</material>
    </gazebo>
    
<transmission name="trans_joint_1">
        <type>transmission_interface/SimpleTransmission</type>
        <joint name="joint_1">
            <hardwareInterface>hardware_interface/PositionJointInterface</hardwareInterface>
        </joint>
        <actuator name="joint_1_motor">
            <hardwareInterface>hardware_interface/PositionJointInterface</hardwareInterface>
            <mechanicalReduction>1</mechanicalReduction>
        </actuator>
    </transmission>
    <transmission name="trans_joint_2">
        <type>transmission_interface/SimpleTransmission</type>
        <joint name="joint_2">
            <hardwareInterface>hardware_interface/PositionJointInterface</hardwareInterface>
        </joint>
        <actuator name="joint_2_motor">
            <hardwareInterface>hardware_interface/PositionJointInterface</hardwareInterface>
            <mechanicalReduction>1</mechanicalReduction>
        </actuator>
    </transmission>
    <transmission name="trans_joint_3">
        <type>transmission_interface/SimpleTransmission</type>
        <joint name="joint_3">
            <hardwareInterface>hardware_interface/PositionJointInterface</hardwareInterface>
        </joint>
        <actuator name="joint_3_motor">
            <hardwareInterface>hardware_interface/PositionJointInterface</hardwareInterface>
            <mechanicalReduction>1</mechanicalReduction>
        </actuator>
    </transmission>
    <transmission name="trans_joint_4">
        <type>transmission_interface/SimpleTransmission</type>
        <joint name="joint_4">
            <hardwareInterface>hardware_interface/PositionJointInterface</hardwareInterface>
        </joint>
        <actuator name="joint_4_motor">
            <hardwareInterface>hardware_interface/PositionJointInterface</hardwareInterface>
            <mechanicalReduction>1</mechanicalReduction>
        </actuator>
    </transmission>
    <transmission name="trans_joint_5">
        <type>transmission_interface/SimpleTransmission</type>
        <joint name="joint_5">
            <hardwareInterface>hardware_interface/PositionJointInterface</hardwareInterface>
        </joint>
        <actuator name="joint_5_motor">
            <hardwareInterface>hardware_interface/PositionJointInterface</hardwareInterface>
            <mechanicalReduction>1</mechanicalReduction>
        </actuator>
    </transmission>
    <transmission name="trans_joint_6">
        <type>transmission_interface/SimpleTransmission</type>
        <joint name="joint_6">
            <hardwareInterface>hardware_interface/PositionJointInterface</hardwareInterface>
        </joint>
        <actuator name="joint_6_motor">
            <hardwareInterface>hardware_interface/PositionJointInterface</hardwareInterface>
            <mechanicalReduction>1</mechanicalReduction>
        </actuator>
    </transmission>
    <gazebo>
        <plugin name="gazebo_ros_control" filename="libgazebo_ros_control.so">
            <robotNamespace>/</robotNamespace>
        </plugin>
    </gazebo>
    <gazebo reference="{prefix}link1">
        <mu1>0.61</mu1>
        <mu2>0.61</mu2>
    </gazebo>

    <gazebo reference="{prefix}link2">
        <mu1>0.61</mu1>
        <mu2>0.61</mu2>
    </gazebo>
    <gazebo reference="{prefix}link3">
        <mu1>0.61</mu1>
        <mu2>0.61</mu2>
    </gazebo>
    <gazebo reference="{prefix}link4">
        <mu1>0.61</mu1>
        <mu2>0.61</mu2>
    </gazebo>
    <gazebo reference="{prefix}link5">
        <mu1>0.61</mu1>
        <mu2>0.61</mu2>
    </gazebo>
    <gazebo reference="{prefix}link6">
        <mu1>0.61</mu1>
        <mu2>0.61</mu2>
    </gazebo>

</robot>
